2024-07-12 22:52:35,226 ERROR An error occured while storing order details to pharm_orders: /home/frank/original_virtual_doctor/routes/user_routes.py 474
Traceback (most recent call last):
  File "/home/frank/.local/lib/python3.10/site-packages/sqlalchemy/engine/base.py", line 1970, in _exec_single_context
    self.dialect.do_execute(
  File "/home/frank/.local/lib/python3.10/site-packages/sqlalchemy/engine/default.py", line 924, in do_execute
    cursor.execute(statement, parameters)
  File "/home/frank/.local/lib/python3.10/site-packages/pymysql/cursors.py", line 153, in execute
    result = self._query(query)
  File "/home/frank/.local/lib/python3.10/site-packages/pymysql/cursors.py", line 322, in _query
    conn.query(q)
  File "/home/frank/.local/lib/python3.10/site-packages/pymysql/connections.py", line 563, in query
    self._affected_rows = self._read_query_result(unbuffered=unbuffered)
  File "/home/frank/.local/lib/python3.10/site-packages/pymysql/connections.py", line 825, in _read_query_result
    result.read()
  File "/home/frank/.local/lib/python3.10/site-packages/pymysql/connections.py", line 1199, in read
    first_packet = self.connection._read_packet()
  File "/home/frank/.local/lib/python3.10/site-packages/pymysql/connections.py", line 775, in _read_packet
    packet.raise_for_error()
  File "/home/frank/.local/lib/python3.10/site-packages/pymysql/protocol.py", line 219, in raise_for_error
    err.raise_mysql_exception(self._data)
  File "/home/frank/.local/lib/python3.10/site-packages/pymysql/err.py", line 150, in raise_mysql_exception
    raise errorclass(errno, errval)
pymysql.err.OperationalError: (1054, "Unknown column 'price' in 'field list'")

The above exception was the direct cause of the following exception:

Traceback (most recent call last):
  File "/home/frank/original_virtual_doctor/routes/user_routes.py", line 472, in pharm_search
    db.session.commit()
  File "/home/frank/.local/lib/python3.10/site-packages/sqlalchemy/orm/scoping.py", line 597, in commit
    return self._proxied.commit()
  File "/home/frank/.local/lib/python3.10/site-packages/sqlalchemy/orm/session.py", line 1972, in commit
    trans.commit(_to_root=True)
  File "<string>", line 2, in commit
  File "/home/frank/.local/lib/python3.10/site-packages/sqlalchemy/orm/state_changes.py", line 139, in _go
    ret_value = fn(self, *arg, **kw)
  File "/home/frank/.local/lib/python3.10/site-packages/sqlalchemy/orm/session.py", line 1257, in commit
    self._prepare_impl()
  File "<string>", line 2, in _prepare_impl
  File "/home/frank/.local/lib/python3.10/site-packages/sqlalchemy/orm/state_changes.py", line 139, in _go
    ret_value = fn(self, *arg, **kw)
  File "/home/frank/.local/lib/python3.10/site-packages/sqlalchemy/orm/session.py", line 1232, in _prepare_impl
    self.session.flush()
  File "/home/frank/.local/lib/python3.10/site-packages/sqlalchemy/orm/session.py", line 4296, in flush
    self._flush(objects)
  File "/home/frank/.local/lib/python3.10/site-packages/sqlalchemy/orm/session.py", line 4431, in _flush
    with util.safe_reraise():
  File "/home/frank/.local/lib/python3.10/site-packages/sqlalchemy/util/langhelpers.py", line 146, in __exit__
    raise exc_value.with_traceback(exc_tb)
  File "/home/frank/.local/lib/python3.10/site-packages/sqlalchemy/orm/session.py", line 4392, in _flush
    flush_context.execute()
  File "/home/frank/.local/lib/python3.10/site-packages/sqlalchemy/orm/unitofwork.py", line 466, in execute
    rec.execute(self)
  File "/home/frank/.local/lib/python3.10/site-packages/sqlalchemy/orm/unitofwork.py", line 642, in execute
    util.preloaded.orm_persistence.save_obj(
  File "/home/frank/.local/lib/python3.10/site-packages/sqlalchemy/orm/persistence.py", line 93, in save_obj
    _emit_insert_statements(
  File "/home/frank/.local/lib/python3.10/site-packages/sqlalchemy/orm/persistence.py", line 1233, in _emit_insert_statements
    result = connection.execute(
  File "/home/frank/.local/lib/python3.10/site-packages/sqlalchemy/engine/base.py", line 1421, in execute
    return meth(
  File "/home/frank/.local/lib/python3.10/site-packages/sqlalchemy/sql/elements.py", line 514, in _execute_on_connection
    return connection._execute_clauseelement(
  File "/home/frank/.local/lib/python3.10/site-packages/sqlalchemy/engine/base.py", line 1643, in _execute_clauseelement
    ret = self._execute_context(
  File "/home/frank/.local/lib/python3.10/site-packages/sqlalchemy/engine/base.py", line 1849, in _execute_context
    return self._exec_single_context(
  File "/home/frank/.local/lib/python3.10/site-packages/sqlalchemy/engine/base.py", line 1989, in _exec_single_context
    self._handle_dbapi_exception(
  File "/home/frank/.local/lib/python3.10/site-packages/sqlalchemy/engine/base.py", line 2356, in _handle_dbapi_exception
    raise sqlalchemy_exception.with_traceback(exc_info[2]) from e
  File "/home/frank/.local/lib/python3.10/site-packages/sqlalchemy/engine/base.py", line 1970, in _exec_single_context
    self.dialect.do_execute(
  File "/home/frank/.local/lib/python3.10/site-packages/sqlalchemy/engine/default.py", line 924, in do_execute
    cursor.execute(statement, parameters)
  File "/home/frank/.local/lib/python3.10/site-packages/pymysql/cursors.py", line 153, in execute
    result = self._query(query)
  File "/home/frank/.local/lib/python3.10/site-packages/pymysql/cursors.py", line 322, in _query
    conn.query(q)
  File "/home/frank/.local/lib/python3.10/site-packages/pymysql/connections.py", line 563, in query
    self._affected_rows = self._read_query_result(unbuffered=unbuffered)
  File "/home/frank/.local/lib/python3.10/site-packages/pymysql/connections.py", line 825, in _read_query_result
    result.read()
  File "/home/frank/.local/lib/python3.10/site-packages/pymysql/connections.py", line 1199, in read
    first_packet = self.connection._read_packet()
  File "/home/frank/.local/lib/python3.10/site-packages/pymysql/connections.py", line 775, in _read_packet
    packet.raise_for_error()
  File "/home/frank/.local/lib/python3.10/site-packages/pymysql/protocol.py", line 219, in raise_for_error
    err.raise_mysql_exception(self._data)
  File "/home/frank/.local/lib/python3.10/site-packages/pymysql/err.py", line 150, in raise_mysql_exception
    raise errorclass(errno, errval)
sqlalchemy.exc.OperationalError: (pymysql.err.OperationalError) (1054, "Unknown column 'price' in 'field list'")
[SQL: INSERT INTO pharm_orders (order_uuid, presc, price, status, user_id) VALUES (%(order_uuid)s, %(presc)s, %(price)s, %(status)s, %(user_id)s)]
[parameters: {'order_uuid': '9b042824-ffed-4722-b01f-ccbf61544608', 'presc': '[{"med_name": "Jj", "dosage": "20 kg"}]', 'price': None, 'status': 'incomplete', 'user_id': None}]
(Background on this error at: https://sqlalche.me/e/20/e3q8)
2024-07-12 22:52:35,234 ERROR An error occured when searching for meds in the databaseThis Session's transaction has been rolled back due to a previous exception during flush. To begin a new transaction with this Session, first issue Session.rollback(). Original exception was: (pymysql.err.OperationalError) (1054, "Unknown column 'price' in 'field list'")
[SQL: INSERT INTO pharm_orders (order_uuid, presc, price, status, user_id) VALUES (%(order_uuid)s, %(presc)s, %(price)s, %(status)s, %(user_id)s)]
[parameters: {'order_uuid': '9b042824-ffed-4722-b01f-ccbf61544608', 'presc': '[{"med_name": "Jj", "dosage": "20 kg"}]', 'price': None, 'status': 'incomplete', 'user_id': None}]
(Background on this error at: https://sqlalche.me/e/20/e3q8) (Background on this error at: https://sqlalche.me/e/20/7s2a): /home/frank/original_virtual_doctor/routes/user_routes.py 504
2024-07-12 22:52:52,415 INFO Uploaded prescription retrieved: /home/frank/original_virtual_doctor/routes/user_routes.py 424
2024-07-12 22:52:52,418 ERROR An error occured while storing order details to pharm_orders: /home/frank/original_virtual_doctor/routes/user_routes.py 474
Traceback (most recent call last):
  File "/home/frank/.local/lib/python3.10/site-packages/sqlalchemy/engine/base.py", line 1970, in _exec_single_context
    self.dialect.do_execute(
  File "/home/frank/.local/lib/python3.10/site-packages/sqlalchemy/engine/default.py", line 924, in do_execute
    cursor.execute(statement, parameters)
  File "/home/frank/.local/lib/python3.10/site-packages/pymysql/cursors.py", line 153, in execute
    result = self._query(query)
  File "/home/frank/.local/lib/python3.10/site-packages/pymysql/cursors.py", line 322, in _query
    conn.query(q)
  File "/home/frank/.local/lib/python3.10/site-packages/pymysql/connections.py", line 563, in query
    self._affected_rows = self._read_query_result(unbuffered=unbuffered)
  File "/home/frank/.local/lib/python3.10/site-packages/pymysql/connections.py", line 825, in _read_query_result
    result.read()
  File "/home/frank/.local/lib/python3.10/site-packages/pymysql/connections.py", line 1199, in read
    first_packet = self.connection._read_packet()
  File "/home/frank/.local/lib/python3.10/site-packages/pymysql/connections.py", line 775, in _read_packet
    packet.raise_for_error()
  File "/home/frank/.local/lib/python3.10/site-packages/pymysql/protocol.py", line 219, in raise_for_error
    err.raise_mysql_exception(self._data)
  File "/home/frank/.local/lib/python3.10/site-packages/pymysql/err.py", line 150, in raise_mysql_exception
    raise errorclass(errno, errval)
pymysql.err.OperationalError: (1054, "Unknown column 'price' in 'field list'")

The above exception was the direct cause of the following exception:

Traceback (most recent call last):
  File "/home/frank/original_virtual_doctor/routes/user_routes.py", line 472, in pharm_search
    db.session.commit()
  File "/home/frank/.local/lib/python3.10/site-packages/sqlalchemy/orm/scoping.py", line 597, in commit
    return self._proxied.commit()
  File "/home/frank/.local/lib/python3.10/site-packages/sqlalchemy/orm/session.py", line 1972, in commit
    trans.commit(_to_root=True)
  File "<string>", line 2, in commit
  File "/home/frank/.local/lib/python3.10/site-packages/sqlalchemy/orm/state_changes.py", line 139, in _go
    ret_value = fn(self, *arg, **kw)
  File "/home/frank/.local/lib/python3.10/site-packages/sqlalchemy/orm/session.py", line 1257, in commit
    self._prepare_impl()
  File "<string>", line 2, in _prepare_impl
  File "/home/frank/.local/lib/python3.10/site-packages/sqlalchemy/orm/state_changes.py", line 139, in _go
    ret_value = fn(self, *arg, **kw)
  File "/home/frank/.local/lib/python3.10/site-packages/sqlalchemy/orm/session.py", line 1232, in _prepare_impl
    self.session.flush()
  File "/home/frank/.local/lib/python3.10/site-packages/sqlalchemy/orm/session.py", line 4296, in flush
    self._flush(objects)
  File "/home/frank/.local/lib/python3.10/site-packages/sqlalchemy/orm/session.py", line 4431, in _flush
    with util.safe_reraise():
  File "/home/frank/.local/lib/python3.10/site-packages/sqlalchemy/util/langhelpers.py", line 146, in __exit__
    raise exc_value.with_traceback(exc_tb)
  File "/home/frank/.local/lib/python3.10/site-packages/sqlalchemy/orm/session.py", line 4392, in _flush
    flush_context.execute()
  File "/home/frank/.local/lib/python3.10/site-packages/sqlalchemy/orm/unitofwork.py", line 466, in execute
    rec.execute(self)
  File "/home/frank/.local/lib/python3.10/site-packages/sqlalchemy/orm/unitofwork.py", line 642, in execute
    util.preloaded.orm_persistence.save_obj(
  File "/home/frank/.local/lib/python3.10/site-packages/sqlalchemy/orm/persistence.py", line 93, in save_obj
    _emit_insert_statements(
  File "/home/frank/.local/lib/python3.10/site-packages/sqlalchemy/orm/persistence.py", line 1233, in _emit_insert_statements
    result = connection.execute(
  File "/home/frank/.local/lib/python3.10/site-packages/sqlalchemy/engine/base.py", line 1421, in execute
    return meth(
  File "/home/frank/.local/lib/python3.10/site-packages/sqlalchemy/sql/elements.py", line 514, in _execute_on_connection
    return connection._execute_clauseelement(
  File "/home/frank/.local/lib/python3.10/site-packages/sqlalchemy/engine/base.py", line 1643, in _execute_clauseelement
    ret = self._execute_context(
  File "/home/frank/.local/lib/python3.10/site-packages/sqlalchemy/engine/base.py", line 1849, in _execute_context
    return self._exec_single_context(
  File "/home/frank/.local/lib/python3.10/site-packages/sqlalchemy/engine/base.py", line 1989, in _exec_single_context
    self._handle_dbapi_exception(
  File "/home/frank/.local/lib/python3.10/site-packages/sqlalchemy/engine/base.py", line 2356, in _handle_dbapi_exception
    raise sqlalchemy_exception.with_traceback(exc_info[2]) from e
  File "/home/frank/.local/lib/python3.10/site-packages/sqlalchemy/engine/base.py", line 1970, in _exec_single_context
    self.dialect.do_execute(
  File "/home/frank/.local/lib/python3.10/site-packages/sqlalchemy/engine/default.py", line 924, in do_execute
    cursor.execute(statement, parameters)
  File "/home/frank/.local/lib/python3.10/site-packages/pymysql/cursors.py", line 153, in execute
    result = self._query(query)
  File "/home/frank/.local/lib/python3.10/site-packages/pymysql/cursors.py", line 322, in _query
    conn.query(q)
  File "/home/frank/.local/lib/python3.10/site-packages/pymysql/connections.py", line 563, in query
    self._affected_rows = self._read_query_result(unbuffered=unbuffered)
  File "/home/frank/.local/lib/python3.10/site-packages/pymysql/connections.py", line 825, in _read_query_result
    result.read()
  File "/home/frank/.local/lib/python3.10/site-packages/pymysql/connections.py", line 1199, in read
    first_packet = self.connection._read_packet()
  File "/home/frank/.local/lib/python3.10/site-packages/pymysql/connections.py", line 775, in _read_packet
    packet.raise_for_error()
  File "/home/frank/.local/lib/python3.10/site-packages/pymysql/protocol.py", line 219, in raise_for_error
    err.raise_mysql_exception(self._data)
  File "/home/frank/.local/lib/python3.10/site-packages/pymysql/err.py", line 150, in raise_mysql_exception
    raise errorclass(errno, errval)
sqlalchemy.exc.OperationalError: (pymysql.err.OperationalError) (1054, "Unknown column 'price' in 'field list'")
[SQL: INSERT INTO pharm_orders (order_uuid, presc, price, status, user_id) VALUES (%(order_uuid)s, %(presc)s, %(price)s, %(status)s, %(user_id)s)]
[parameters: {'order_uuid': '349a16dc-4e52-4f95-a9f4-3b5b2e9990f6', 'presc': '[{"med_name": "Sodium", "dosage": "20 kg"}]', 'price': None, 'status': 'incomplete', 'user_id': None}]
(Background on this error at: https://sqlalche.me/e/20/e3q8)
2024-07-12 22:52:52,421 ERROR An error occured when searching for meds in the databaseThis Session's transaction has been rolled back due to a previous exception during flush. To begin a new transaction with this Session, first issue Session.rollback(). Original exception was: (pymysql.err.OperationalError) (1054, "Unknown column 'price' in 'field list'")
[SQL: INSERT INTO pharm_orders (order_uuid, presc, price, status, user_id) VALUES (%(order_uuid)s, %(presc)s, %(price)s, %(status)s, %(user_id)s)]
[parameters: {'order_uuid': '349a16dc-4e52-4f95-a9f4-3b5b2e9990f6', 'presc': '[{"med_name": "Sodium", "dosage": "20 kg"}]', 'price': None, 'status': 'incomplete', 'user_id': None}]
(Background on this error at: https://sqlalche.me/e/20/e3q8) (Background on this error at: https://sqlalche.me/e/20/7s2a): /home/frank/original_virtual_doctor/routes/user_routes.py 504
2024-07-12 22:53:00,610 INFO Uploaded prescription retrieved: /home/frank/original_virtual_doctor/routes/user_routes.py 424
2024-07-12 22:53:00,619 ERROR An error occured while storing order details to pharm_orders: /home/frank/original_virtual_doctor/routes/user_routes.py 474
Traceback (most recent call last):
  File "/home/frank/.local/lib/python3.10/site-packages/sqlalchemy/engine/base.py", line 1970, in _exec_single_context
    self.dialect.do_execute(
  File "/home/frank/.local/lib/python3.10/site-packages/sqlalchemy/engine/default.py", line 924, in do_execute
    cursor.execute(statement, parameters)
  File "/home/frank/.local/lib/python3.10/site-packages/pymysql/cursors.py", line 153, in execute
    result = self._query(query)
  File "/home/frank/.local/lib/python3.10/site-packages/pymysql/cursors.py", line 322, in _query
    conn.query(q)
  File "/home/frank/.local/lib/python3.10/site-packages/pymysql/connections.py", line 563, in query
    self._affected_rows = self._read_query_result(unbuffered=unbuffered)
  File "/home/frank/.local/lib/python3.10/site-packages/pymysql/connections.py", line 825, in _read_query_result
    result.read()
  File "/home/frank/.local/lib/python3.10/site-packages/pymysql/connections.py", line 1199, in read
    first_packet = self.connection._read_packet()
  File "/home/frank/.local/lib/python3.10/site-packages/pymysql/connections.py", line 775, in _read_packet
    packet.raise_for_error()
  File "/home/frank/.local/lib/python3.10/site-packages/pymysql/protocol.py", line 219, in raise_for_error
    err.raise_mysql_exception(self._data)
  File "/home/frank/.local/lib/python3.10/site-packages/pymysql/err.py", line 150, in raise_mysql_exception
    raise errorclass(errno, errval)
pymysql.err.OperationalError: (1054, "Unknown column 'price' in 'field list'")

The above exception was the direct cause of the following exception:

Traceback (most recent call last):
  File "/home/frank/original_virtual_doctor/routes/user_routes.py", line 472, in pharm_search
    db.session.commit()
  File "/home/frank/.local/lib/python3.10/site-packages/sqlalchemy/orm/scoping.py", line 597, in commit
    return self._proxied.commit()
  File "/home/frank/.local/lib/python3.10/site-packages/sqlalchemy/orm/session.py", line 1972, in commit
    trans.commit(_to_root=True)
  File "<string>", line 2, in commit
  File "/home/frank/.local/lib/python3.10/site-packages/sqlalchemy/orm/state_changes.py", line 139, in _go
    ret_value = fn(self, *arg, **kw)
  File "/home/frank/.local/lib/python3.10/site-packages/sqlalchemy/orm/session.py", line 1257, in commit
    self._prepare_impl()
  File "<string>", line 2, in _prepare_impl
  File "/home/frank/.local/lib/python3.10/site-packages/sqlalchemy/orm/state_changes.py", line 139, in _go
    ret_value = fn(self, *arg, **kw)
  File "/home/frank/.local/lib/python3.10/site-packages/sqlalchemy/orm/session.py", line 1232, in _prepare_impl
    self.session.flush()
  File "/home/frank/.local/lib/python3.10/site-packages/sqlalchemy/orm/session.py", line 4296, in flush
    self._flush(objects)
  File "/home/frank/.local/lib/python3.10/site-packages/sqlalchemy/orm/session.py", line 4431, in _flush
    with util.safe_reraise():
  File "/home/frank/.local/lib/python3.10/site-packages/sqlalchemy/util/langhelpers.py", line 146, in __exit__
    raise exc_value.with_traceback(exc_tb)
  File "/home/frank/.local/lib/python3.10/site-packages/sqlalchemy/orm/session.py", line 4392, in _flush
    flush_context.execute()
  File "/home/frank/.local/lib/python3.10/site-packages/sqlalchemy/orm/unitofwork.py", line 466, in execute
    rec.execute(self)
  File "/home/frank/.local/lib/python3.10/site-packages/sqlalchemy/orm/unitofwork.py", line 642, in execute
    util.preloaded.orm_persistence.save_obj(
  File "/home/frank/.local/lib/python3.10/site-packages/sqlalchemy/orm/persistence.py", line 93, in save_obj
    _emit_insert_statements(
  File "/home/frank/.local/lib/python3.10/site-packages/sqlalchemy/orm/persistence.py", line 1233, in _emit_insert_statements
    result = connection.execute(
  File "/home/frank/.local/lib/python3.10/site-packages/sqlalchemy/engine/base.py", line 1421, in execute
    return meth(
  File "/home/frank/.local/lib/python3.10/site-packages/sqlalchemy/sql/elements.py", line 514, in _execute_on_connection
    return connection._execute_clauseelement(
  File "/home/frank/.local/lib/python3.10/site-packages/sqlalchemy/engine/base.py", line 1643, in _execute_clauseelement
    ret = self._execute_context(
  File "/home/frank/.local/lib/python3.10/site-packages/sqlalchemy/engine/base.py", line 1849, in _execute_context
    return self._exec_single_context(
  File "/home/frank/.local/lib/python3.10/site-packages/sqlalchemy/engine/base.py", line 1989, in _exec_single_context
    self._handle_dbapi_exception(
  File "/home/frank/.local/lib/python3.10/site-packages/sqlalchemy/engine/base.py", line 2356, in _handle_dbapi_exception
    raise sqlalchemy_exception.with_traceback(exc_info[2]) from e
  File "/home/frank/.local/lib/python3.10/site-packages/sqlalchemy/engine/base.py", line 1970, in _exec_single_context
    self.dialect.do_execute(
  File "/home/frank/.local/lib/python3.10/site-packages/sqlalchemy/engine/default.py", line 924, in do_execute
    cursor.execute(statement, parameters)
  File "/home/frank/.local/lib/python3.10/site-packages/pymysql/cursors.py", line 153, in execute
    result = self._query(query)
  File "/home/frank/.local/lib/python3.10/site-packages/pymysql/cursors.py", line 322, in _query
    conn.query(q)
  File "/home/frank/.local/lib/python3.10/site-packages/pymysql/connections.py", line 563, in query
    self._affected_rows = self._read_query_result(unbuffered=unbuffered)
  File "/home/frank/.local/lib/python3.10/site-packages/pymysql/connections.py", line 825, in _read_query_result
    result.read()
  File "/home/frank/.local/lib/python3.10/site-packages/pymysql/connections.py", line 1199, in read
    first_packet = self.connection._read_packet()
  File "/home/frank/.local/lib/python3.10/site-packages/pymysql/connections.py", line 775, in _read_packet
    packet.raise_for_error()
  File "/home/frank/.local/lib/python3.10/site-packages/pymysql/protocol.py", line 219, in raise_for_error
    err.raise_mysql_exception(self._data)
  File "/home/frank/.local/lib/python3.10/site-packages/pymysql/err.py", line 150, in raise_mysql_exception
    raise errorclass(errno, errval)
sqlalchemy.exc.OperationalError: (pymysql.err.OperationalError) (1054, "Unknown column 'price' in 'field list'")
[SQL: INSERT INTO pharm_orders (order_uuid, presc, price, status, user_id) VALUES (%(order_uuid)s, %(presc)s, %(price)s, %(status)s, %(user_id)s)]
[parameters: {'order_uuid': '7756a5ac-4d70-4751-9cd9-afcd452ad3a5', 'presc': '[{"med_name": "sodium", "dosage": "20 kg"}]', 'price': None, 'status': 'incomplete', 'user_id': None}]
(Background on this error at: https://sqlalche.me/e/20/e3q8)
2024-07-12 22:53:00,627 ERROR An error occured when searching for meds in the databaseThis Session's transaction has been rolled back due to a previous exception during flush. To begin a new transaction with this Session, first issue Session.rollback(). Original exception was: (pymysql.err.OperationalError) (1054, "Unknown column 'price' in 'field list'")
[SQL: INSERT INTO pharm_orders (order_uuid, presc, price, status, user_id) VALUES (%(order_uuid)s, %(presc)s, %(price)s, %(status)s, %(user_id)s)]
[parameters: {'order_uuid': '7756a5ac-4d70-4751-9cd9-afcd452ad3a5', 'presc': '[{"med_name": "sodium", "dosage": "20 kg"}]', 'price': None, 'status': 'incomplete', 'user_id': None}]
(Background on this error at: https://sqlalche.me/e/20/e3q8) (Background on this error at: https://sqlalche.me/e/20/7s2a): /home/frank/original_virtual_doctor/routes/user_routes.py 504
2024-07-12 22:56:24,184 INFO Homepage accessed: /home/frank/original_virtual_doctor/routes/public_routes.py 18
2024-07-12 23:39:10,508 INFO Logging setup successfully: /home/frank/original_virtual_doctor/./app.py 28
2024-07-12 23:39:10,509 INFO DataBase set up successfully: /home/frank/original_virtual_doctor/./app.py 40
2024-07-12 23:39:10,621 INFO Migrations set up successfully: /home/frank/original_virtual_doctor/./app.py 52
2024-07-12 23:39:10,639 INFO Blueprints registered successfully: /home/frank/original_virtual_doctor/./app.py 60
2024-07-12 23:39:10,639 INFO Mail service setup successfully: /home/frank/original_virtual_doctor/./app.py 73
2024-07-12 23:39:10,639 INFO App created successfully: /home/frank/original_virtual_doctor/./app.py 83
2024-07-12 23:39:18,242 INFO Homepage accessed: /home/frank/original_virtual_doctor/routes/public_routes.py 18
2024-07-12 23:39:35,113 INFO Uploaded prescription retrieved: /home/frank/original_virtual_doctor/routes/user_routes.py 424
2024-07-12 23:39:35,120 ERROR An error occured while storing order details to pharm_orders: /home/frank/original_virtual_doctor/routes/user_routes.py 475
Traceback (most recent call last):
  File "/home/frank/.local/lib/python3.10/site-packages/sqlalchemy/engine/base.py", line 1970, in _exec_single_context
    self.dialect.do_execute(
  File "/home/frank/.local/lib/python3.10/site-packages/sqlalchemy/engine/default.py", line 924, in do_execute
    cursor.execute(statement, parameters)
  File "/home/frank/.local/lib/python3.10/site-packages/pymysql/cursors.py", line 153, in execute
    result = self._query(query)
  File "/home/frank/.local/lib/python3.10/site-packages/pymysql/cursors.py", line 322, in _query
    conn.query(q)
  File "/home/frank/.local/lib/python3.10/site-packages/pymysql/connections.py", line 563, in query
    self._affected_rows = self._read_query_result(unbuffered=unbuffered)
  File "/home/frank/.local/lib/python3.10/site-packages/pymysql/connections.py", line 825, in _read_query_result
    result.read()
  File "/home/frank/.local/lib/python3.10/site-packages/pymysql/connections.py", line 1199, in read
    first_packet = self.connection._read_packet()
  File "/home/frank/.local/lib/python3.10/site-packages/pymysql/connections.py", line 775, in _read_packet
    packet.raise_for_error()
  File "/home/frank/.local/lib/python3.10/site-packages/pymysql/protocol.py", line 219, in raise_for_error
    err.raise_mysql_exception(self._data)
  File "/home/frank/.local/lib/python3.10/site-packages/pymysql/err.py", line 150, in raise_mysql_exception
    raise errorclass(errno, errval)
pymysql.err.OperationalError: (1054, "Unknown column 'price' in 'field list'")

The above exception was the direct cause of the following exception:

Traceback (most recent call last):
  File "/home/frank/original_virtual_doctor/routes/user_routes.py", line 472, in pharm_search
    db.session.commit()
  File "/home/frank/.local/lib/python3.10/site-packages/sqlalchemy/orm/scoping.py", line 597, in commit
    return self._proxied.commit()
  File "/home/frank/.local/lib/python3.10/site-packages/sqlalchemy/orm/session.py", line 1972, in commit
    trans.commit(_to_root=True)
  File "<string>", line 2, in commit
  File "/home/frank/.local/lib/python3.10/site-packages/sqlalchemy/orm/state_changes.py", line 139, in _go
    ret_value = fn(self, *arg, **kw)
  File "/home/frank/.local/lib/python3.10/site-packages/sqlalchemy/orm/session.py", line 1257, in commit
    self._prepare_impl()
  File "<string>", line 2, in _prepare_impl
  File "/home/frank/.local/lib/python3.10/site-packages/sqlalchemy/orm/state_changes.py", line 139, in _go
    ret_value = fn(self, *arg, **kw)
  File "/home/frank/.local/lib/python3.10/site-packages/sqlalchemy/orm/session.py", line 1232, in _prepare_impl
    self.session.flush()
  File "/home/frank/.local/lib/python3.10/site-packages/sqlalchemy/orm/session.py", line 4296, in flush
    self._flush(objects)
  File "/home/frank/.local/lib/python3.10/site-packages/sqlalchemy/orm/session.py", line 4431, in _flush
    with util.safe_reraise():
  File "/home/frank/.local/lib/python3.10/site-packages/sqlalchemy/util/langhelpers.py", line 146, in __exit__
    raise exc_value.with_traceback(exc_tb)
  File "/home/frank/.local/lib/python3.10/site-packages/sqlalchemy/orm/session.py", line 4392, in _flush
    flush_context.execute()
  File "/home/frank/.local/lib/python3.10/site-packages/sqlalchemy/orm/unitofwork.py", line 466, in execute
    rec.execute(self)
  File "/home/frank/.local/lib/python3.10/site-packages/sqlalchemy/orm/unitofwork.py", line 642, in execute
    util.preloaded.orm_persistence.save_obj(
  File "/home/frank/.local/lib/python3.10/site-packages/sqlalchemy/orm/persistence.py", line 93, in save_obj
    _emit_insert_statements(
  File "/home/frank/.local/lib/python3.10/site-packages/sqlalchemy/orm/persistence.py", line 1233, in _emit_insert_statements
    result = connection.execute(
  File "/home/frank/.local/lib/python3.10/site-packages/sqlalchemy/engine/base.py", line 1421, in execute
    return meth(
  File "/home/frank/.local/lib/python3.10/site-packages/sqlalchemy/sql/elements.py", line 514, in _execute_on_connection
    return connection._execute_clauseelement(
  File "/home/frank/.local/lib/python3.10/site-packages/sqlalchemy/engine/base.py", line 1643, in _execute_clauseelement
    ret = self._execute_context(
  File "/home/frank/.local/lib/python3.10/site-packages/sqlalchemy/engine/base.py", line 1849, in _execute_context
    return self._exec_single_context(
  File "/home/frank/.local/lib/python3.10/site-packages/sqlalchemy/engine/base.py", line 1989, in _exec_single_context
    self._handle_dbapi_exception(
  File "/home/frank/.local/lib/python3.10/site-packages/sqlalchemy/engine/base.py", line 2356, in _handle_dbapi_exception
    raise sqlalchemy_exception.with_traceback(exc_info[2]) from e
  File "/home/frank/.local/lib/python3.10/site-packages/sqlalchemy/engine/base.py", line 1970, in _exec_single_context
    self.dialect.do_execute(
  File "/home/frank/.local/lib/python3.10/site-packages/sqlalchemy/engine/default.py", line 924, in do_execute
    cursor.execute(statement, parameters)
  File "/home/frank/.local/lib/python3.10/site-packages/pymysql/cursors.py", line 153, in execute
    result = self._query(query)
  File "/home/frank/.local/lib/python3.10/site-packages/pymysql/cursors.py", line 322, in _query
    conn.query(q)
  File "/home/frank/.local/lib/python3.10/site-packages/pymysql/connections.py", line 563, in query
    self._affected_rows = self._read_query_result(unbuffered=unbuffered)
  File "/home/frank/.local/lib/python3.10/site-packages/pymysql/connections.py", line 825, in _read_query_result
    result.read()
  File "/home/frank/.local/lib/python3.10/site-packages/pymysql/connections.py", line 1199, in read
    first_packet = self.connection._read_packet()
  File "/home/frank/.local/lib/python3.10/site-packages/pymysql/connections.py", line 775, in _read_packet
    packet.raise_for_error()
  File "/home/frank/.local/lib/python3.10/site-packages/pymysql/protocol.py", line 219, in raise_for_error
    err.raise_mysql_exception(self._data)
  File "/home/frank/.local/lib/python3.10/site-packages/pymysql/err.py", line 150, in raise_mysql_exception
    raise errorclass(errno, errval)
sqlalchemy.exc.OperationalError: (pymysql.err.OperationalError) (1054, "Unknown column 'price' in 'field list'")
[SQL: INSERT INTO pharm_orders (order_uuid, presc, price, status, user_id) VALUES (%(order_uuid)s, %(presc)s, %(price)s, %(status)s, %(user_id)s)]
[parameters: {'order_uuid': '68c976fc-f606-4b8d-a368-80f5d1d7936f', 'presc': '[{"med_name": "Sodium", "dosage": "Y"}]', 'price': None, 'status': 'incomplete', 'user_id': None}]
(Background on this error at: https://sqlalche.me/e/20/e3q8)
2024-07-12 23:39:35,172 INFO Prescription searched in database: /home/frank/original_virtual_doctor/routes/user_routes.py 503
2024-07-12 23:39:40,226 WARNING An error occurred when searching for the pharmacy selected or to make an order: /home/frank/original_virtual_doctor/routes/user_routes.py 534
Traceback (most recent call last):
  File "/home/frank/original_virtual_doctor/routes/user_routes.py", line 528, in pharm_orders
    pharm = db.session.query(Pharmacy)._filter_by(pharm_uuid=pharm_uuid).first()
AttributeError: 'Query' object has no attribute '_filter_by'
2024-07-12 23:41:21,564 INFO Logging setup successfully: /home/frank/original_virtual_doctor/./app.py 28
2024-07-12 23:41:21,564 INFO DataBase set up successfully: /home/frank/original_virtual_doctor/./app.py 40
2024-07-12 23:41:21,893 INFO Migrations set up successfully: /home/frank/original_virtual_doctor/./app.py 52
2024-07-12 23:41:21,953 INFO Blueprints registered successfully: /home/frank/original_virtual_doctor/./app.py 60
2024-07-12 23:41:21,954 INFO Mail service setup successfully: /home/frank/original_virtual_doctor/./app.py 73
2024-07-12 23:41:21,954 INFO App created successfully: /home/frank/original_virtual_doctor/./app.py 83
2024-07-12 23:41:23,550 INFO Logging setup successfully: /home/frank/original_virtual_doctor/./app.py 28
2024-07-12 23:41:23,551 INFO DataBase set up successfully: /home/frank/original_virtual_doctor/./app.py 40
2024-07-12 23:41:23,659 INFO Migrations set up successfully: /home/frank/original_virtual_doctor/./app.py 52
2024-07-12 23:41:23,679 INFO Blueprints registered successfully: /home/frank/original_virtual_doctor/./app.py 60
2024-07-12 23:41:23,679 INFO Mail service setup successfully: /home/frank/original_virtual_doctor/./app.py 73
2024-07-12 23:41:23,679 INFO App created successfully: /home/frank/original_virtual_doctor/./app.py 83
2024-07-12 23:41:25,194 INFO Logging setup successfully: /home/frank/original_virtual_doctor/./app.py 28
2024-07-12 23:41:25,194 INFO DataBase set up successfully: /home/frank/original_virtual_doctor/./app.py 40
2024-07-12 23:41:25,480 INFO Migrations set up successfully: /home/frank/original_virtual_doctor/./app.py 52
2024-07-12 23:41:25,504 INFO Blueprints registered successfully: /home/frank/original_virtual_doctor/./app.py 60
2024-07-12 23:41:25,504 INFO Mail service setup successfully: /home/frank/original_virtual_doctor/./app.py 73
2024-07-12 23:41:25,504 INFO App created successfully: /home/frank/original_virtual_doctor/./app.py 83
2024-07-12 23:41:28,289 INFO Logging setup successfully: /home/frank/original_virtual_doctor/./app.py 28
2024-07-12 23:41:28,289 INFO DataBase set up successfully: /home/frank/original_virtual_doctor/./app.py 40
2024-07-12 23:41:28,377 INFO Migrations set up successfully: /home/frank/original_virtual_doctor/./app.py 52
2024-07-12 23:41:28,394 INFO Blueprints registered successfully: /home/frank/original_virtual_doctor/./app.py 60
2024-07-12 23:41:28,394 INFO Mail service setup successfully: /home/frank/original_virtual_doctor/./app.py 73
2024-07-12 23:41:28,394 INFO App created successfully: /home/frank/original_virtual_doctor/./app.py 83
2024-07-12 23:41:31,100 INFO Logging setup successfully: /home/frank/original_virtual_doctor/./app.py 28
2024-07-12 23:41:31,100 INFO DataBase set up successfully: /home/frank/original_virtual_doctor/./app.py 40
2024-07-12 23:41:31,180 INFO Migrations set up successfully: /home/frank/original_virtual_doctor/./app.py 52
2024-07-12 23:41:31,199 INFO Blueprints registered successfully: /home/frank/original_virtual_doctor/./app.py 60
2024-07-12 23:41:31,200 INFO Mail service setup successfully: /home/frank/original_virtual_doctor/./app.py 73
2024-07-12 23:41:31,200 INFO App created successfully: /home/frank/original_virtual_doctor/./app.py 83
2024-07-12 23:44:30,858 INFO Logging setup successfully: /home/frank/original_virtual_doctor/app.py 28
2024-07-12 23:44:30,858 INFO DataBase set up successfully: /home/frank/original_virtual_doctor/app.py 40
2024-07-12 23:44:31,036 INFO Migrations set up successfully: /home/frank/original_virtual_doctor/app.py 52
2024-07-12 23:44:31,054 INFO Blueprints registered successfully: /home/frank/original_virtual_doctor/app.py 60
2024-07-12 23:44:31,054 INFO Mail service setup successfully: /home/frank/original_virtual_doctor/app.py 73
2024-07-12 23:44:31,054 INFO App created successfully: /home/frank/original_virtual_doctor/app.py 83
2024-07-12 23:44:45,787 INFO Logging setup successfully: /home/frank/original_virtual_doctor/app.py 28
2024-07-12 23:44:45,788 INFO DataBase set up successfully: /home/frank/original_virtual_doctor/app.py 40
2024-07-12 23:44:45,996 INFO Migrations set up successfully: /home/frank/original_virtual_doctor/app.py 52
2024-07-12 23:44:46,017 INFO Blueprints registered successfully: /home/frank/original_virtual_doctor/app.py 60
2024-07-12 23:44:46,017 INFO Mail service setup successfully: /home/frank/original_virtual_doctor/app.py 73
2024-07-12 23:44:46,017 INFO App created successfully: /home/frank/original_virtual_doctor/app.py 83
2024-07-12 23:47:19,924 INFO Logging setup successfully: /home/frank/original_virtual_doctor/app.py 28
2024-07-12 23:47:19,925 INFO DataBase set up successfully: /home/frank/original_virtual_doctor/app.py 40
2024-07-12 23:47:25,647 INFO Migrations set up successfully: /home/frank/original_virtual_doctor/app.py 52
2024-07-12 23:47:25,687 INFO Blueprints registered successfully: /home/frank/original_virtual_doctor/app.py 60
2024-07-12 23:47:25,687 INFO Mail service setup successfully: /home/frank/original_virtual_doctor/app.py 73
2024-07-12 23:47:25,688 INFO App created successfully: /home/frank/original_virtual_doctor/app.py 83
2024-07-12 23:48:31,178 INFO Logging setup successfully: /home/frank/original_virtual_doctor/app.py 28
2024-07-12 23:48:31,178 INFO DataBase set up successfully: /home/frank/original_virtual_doctor/app.py 40
2024-07-12 23:48:31,385 INFO Migrations set up successfully: /home/frank/original_virtual_doctor/app.py 52
2024-07-12 23:48:31,407 INFO Blueprints registered successfully: /home/frank/original_virtual_doctor/app.py 60
2024-07-12 23:48:31,407 INFO Mail service setup successfully: /home/frank/original_virtual_doctor/app.py 73
2024-07-12 23:48:31,407 INFO App created successfully: /home/frank/original_virtual_doctor/app.py 83
2024-07-12 23:48:33,021 INFO Logging setup successfully: /home/frank/original_virtual_doctor/./app.py 28
2024-07-12 23:48:33,021 INFO DataBase set up successfully: /home/frank/original_virtual_doctor/./app.py 40
2024-07-12 23:48:33,200 INFO Migrations set up successfully: /home/frank/original_virtual_doctor/./app.py 52
2024-07-12 23:48:33,221 INFO Blueprints registered successfully: /home/frank/original_virtual_doctor/./app.py 60
2024-07-12 23:48:33,221 INFO Mail service setup successfully: /home/frank/original_virtual_doctor/./app.py 73
2024-07-12 23:48:33,221 INFO App created successfully: /home/frank/original_virtual_doctor/./app.py 83
2024-07-12 23:48:52,478 INFO Logging setup successfully: /home/frank/original_virtual_doctor/app.py 28
2024-07-12 23:48:52,479 INFO DataBase set up successfully: /home/frank/original_virtual_doctor/app.py 40
2024-07-12 23:48:52,558 INFO Migrations set up successfully: /home/frank/original_virtual_doctor/app.py 52
2024-07-12 23:48:52,579 INFO Blueprints registered successfully: /home/frank/original_virtual_doctor/app.py 60
2024-07-12 23:48:52,579 INFO Mail service setup successfully: /home/frank/original_virtual_doctor/app.py 73
2024-07-12 23:48:52,579 INFO App created successfully: /home/frank/original_virtual_doctor/app.py 83
2024-07-12 23:49:35,340 INFO Logging setup successfully: /home/frank/original_virtual_doctor/app.py 28
2024-07-12 23:49:35,340 INFO DataBase set up successfully: /home/frank/original_virtual_doctor/app.py 40
2024-07-12 23:49:35,527 INFO Migrations set up successfully: /home/frank/original_virtual_doctor/app.py 52
2024-07-12 23:49:35,547 INFO Blueprints registered successfully: /home/frank/original_virtual_doctor/app.py 60
2024-07-12 23:49:35,547 INFO Mail service setup successfully: /home/frank/original_virtual_doctor/app.py 73
2024-07-12 23:49:35,547 INFO App created successfully: /home/frank/original_virtual_doctor/app.py 83
2024-07-12 23:49:37,377 INFO Logging setup successfully: /home/frank/original_virtual_doctor/./app.py 28
2024-07-12 23:49:37,377 INFO DataBase set up successfully: /home/frank/original_virtual_doctor/./app.py 40
2024-07-12 23:49:37,558 INFO Migrations set up successfully: /home/frank/original_virtual_doctor/./app.py 52
2024-07-12 23:49:37,581 INFO Blueprints registered successfully: /home/frank/original_virtual_doctor/./app.py 60
2024-07-12 23:49:37,581 INFO Mail service setup successfully: /home/frank/original_virtual_doctor/./app.py 73
2024-07-12 23:49:37,581 INFO App created successfully: /home/frank/original_virtual_doctor/./app.py 83
2024-07-12 23:49:41,192 INFO Logging setup successfully: /home/frank/original_virtual_doctor/app.py 28
2024-07-12 23:49:41,192 INFO DataBase set up successfully: /home/frank/original_virtual_doctor/app.py 40
2024-07-12 23:49:41,415 INFO Migrations set up successfully: /home/frank/original_virtual_doctor/app.py 52
2024-07-12 23:49:41,442 INFO Blueprints registered successfully: /home/frank/original_virtual_doctor/app.py 60
2024-07-12 23:49:41,442 INFO Mail service setup successfully: /home/frank/original_virtual_doctor/app.py 73
2024-07-12 23:49:41,442 INFO App created successfully: /home/frank/original_virtual_doctor/app.py 83
2024-07-12 23:49:52,673 INFO Logging setup successfully: /home/frank/original_virtual_doctor/app.py 28
2024-07-12 23:49:52,673 INFO DataBase set up successfully: /home/frank/original_virtual_doctor/app.py 40
2024-07-12 23:49:52,805 INFO Migrations set up successfully: /home/frank/original_virtual_doctor/app.py 52
2024-07-12 23:49:52,830 INFO Blueprints registered successfully: /home/frank/original_virtual_doctor/app.py 60
2024-07-12 23:49:52,830 INFO Mail service setup successfully: /home/frank/original_virtual_doctor/app.py 73
2024-07-12 23:49:52,831 INFO App created successfully: /home/frank/original_virtual_doctor/app.py 83
2024-07-12 23:50:40,957 INFO Uploaded prescription retrieved: /home/frank/original_virtual_doctor/routes/user_routes.py 424
2024-07-12 23:50:41,667 INFO Prescription searched in database: /home/frank/original_virtual_doctor/routes/user_routes.py 503
2024-07-12 23:52:34,984 INFO Logging setup successfully: /home/frank/original_virtual_doctor/./app.py 28
2024-07-12 23:52:34,984 INFO DataBase set up successfully: /home/frank/original_virtual_doctor/./app.py 40
2024-07-12 23:52:35,199 INFO Migrations set up successfully: /home/frank/original_virtual_doctor/./app.py 52
2024-07-12 23:52:35,219 INFO Blueprints registered successfully: /home/frank/original_virtual_doctor/./app.py 60
2024-07-12 23:52:35,220 INFO Mail service setup successfully: /home/frank/original_virtual_doctor/./app.py 73
2024-07-12 23:52:35,220 INFO App created successfully: /home/frank/original_virtual_doctor/./app.py 83
2024-07-13 00:30:28,410 INFO Logging setup successfully: /home/frank/original_virtual_doctor/./app.py 28
2024-07-13 00:30:28,410 INFO DataBase set up successfully: /home/frank/original_virtual_doctor/./app.py 40
2024-07-13 00:30:28,573 INFO Migrations set up successfully: /home/frank/original_virtual_doctor/./app.py 52
2024-07-13 00:30:28,602 INFO Blueprints registered successfully: /home/frank/original_virtual_doctor/./app.py 60
2024-07-13 00:30:28,603 INFO Mail service setup successfully: /home/frank/original_virtual_doctor/./app.py 73
2024-07-13 00:30:28,603 INFO App created successfully: /home/frank/original_virtual_doctor/./app.py 83
2024-07-13 00:30:29,598 INFO Logging setup successfully: /home/frank/original_virtual_doctor/./app.py 28
2024-07-13 00:30:29,599 INFO DataBase set up successfully: /home/frank/original_virtual_doctor/./app.py 40
2024-07-13 00:30:29,849 INFO Migrations set up successfully: /home/frank/original_virtual_doctor/./app.py 52
2024-07-13 00:30:29,879 INFO Blueprints registered successfully: /home/frank/original_virtual_doctor/./app.py 60
2024-07-13 00:30:29,880 INFO Mail service setup successfully: /home/frank/original_virtual_doctor/./app.py 73
2024-07-13 00:30:29,880 INFO App created successfully: /home/frank/original_virtual_doctor/./app.py 83
2024-07-13 00:31:05,216 INFO Uploaded prescription retrieved: /home/frank/original_virtual_doctor/routes/user_routes.py 424
2024-07-13 00:31:06,487 INFO Prescription searched in database: /home/frank/original_virtual_doctor/routes/user_routes.py 503
2024-07-13 00:31:08,386 INFO Homepage accessed: /home/frank/original_virtual_doctor/routes/public_routes.py 18
2024-07-13 00:31:23,742 INFO Uploaded prescription retrieved: /home/frank/original_virtual_doctor/routes/user_routes.py 424
2024-07-13 00:31:24,344 INFO Prescription searched in database: /home/frank/original_virtual_doctor/routes/user_routes.py 503
2024-07-13 00:32:00,213 INFO Uploaded prescription retrieved: /home/frank/original_virtual_doctor/routes/user_routes.py 424
2024-07-13 00:32:01,403 INFO Prescription searched in database: /home/frank/original_virtual_doctor/routes/user_routes.py 503
2024-07-13 00:34:30,617 INFO Uploaded prescription retrieved: /home/frank/original_virtual_doctor/routes/user_routes.py 424
2024-07-13 00:34:31,004 INFO Prescription searched in database: /home/frank/original_virtual_doctor/routes/user_routes.py 503
2024-07-13 00:37:08,413 INFO Uploaded prescription retrieved: /home/frank/original_virtual_doctor/routes/user_routes.py 424
2024-07-13 00:37:09,029 INFO Prescription searched in database: /home/frank/original_virtual_doctor/routes/user_routes.py 503
2024-07-13 00:37:23,926 INFO Uploaded prescription retrieved: /home/frank/original_virtual_doctor/routes/user_routes.py 424
2024-07-13 00:37:24,278 INFO Prescription searched in database: /home/frank/original_virtual_doctor/routes/user_routes.py 503
2024-07-13 00:38:18,653 INFO Uploaded prescription retrieved: /home/frank/original_virtual_doctor/routes/user_routes.py 424
2024-07-13 00:38:19,471 INFO Prescription searched in database: /home/frank/original_virtual_doctor/routes/user_routes.py 503
2024-07-13 00:38:28,241 INFO Uploaded prescription retrieved: /home/frank/original_virtual_doctor/routes/user_routes.py 424
2024-07-13 00:38:28,839 INFO Prescription searched in database: /home/frank/original_virtual_doctor/routes/user_routes.py 503
2024-07-13 00:41:50,925 INFO Uploaded prescription retrieved: /home/frank/original_virtual_doctor/routes/user_routes.py 424
2024-07-13 00:41:51,495 INFO Prescription searched in database: /home/frank/original_virtual_doctor/routes/user_routes.py 503
2024-07-13 00:44:53,761 INFO Logging setup successfully: /home/frank/original_virtual_doctor/./app.py 28
2024-07-13 00:44:53,762 INFO DataBase set up successfully: /home/frank/original_virtual_doctor/./app.py 40
2024-07-13 00:44:53,981 INFO Migrations set up successfully: /home/frank/original_virtual_doctor/./app.py 52
2024-07-13 00:44:53,999 INFO Blueprints registered successfully: /home/frank/original_virtual_doctor/./app.py 60
2024-07-13 00:44:54,000 INFO Mail service setup successfully: /home/frank/original_virtual_doctor/./app.py 73
2024-07-13 00:44:54,000 INFO App created successfully: /home/frank/original_virtual_doctor/./app.py 83
2024-07-13 00:45:43,246 INFO Uploaded prescription retrieved: /home/frank/original_virtual_doctor/routes/user_routes.py 424
2024-07-13 00:45:44,249 INFO Prescription searched in database: /home/frank/original_virtual_doctor/routes/user_routes.py 503
2024-07-13 00:45:47,388 INFO Logging setup successfully: /home/frank/original_virtual_doctor/app.py 28
2024-07-13 00:45:47,389 INFO DataBase set up successfully: /home/frank/original_virtual_doctor/app.py 40
2024-07-13 00:45:47,894 INFO Migrations set up successfully: /home/frank/original_virtual_doctor/app.py 52
2024-07-13 00:45:47,911 INFO Blueprints registered successfully: /home/frank/original_virtual_doctor/app.py 60
2024-07-13 00:45:47,911 INFO Mail service setup successfully: /home/frank/original_virtual_doctor/app.py 73
2024-07-13 00:45:47,911 INFO App created successfully: /home/frank/original_virtual_doctor/app.py 83
2024-07-13 00:45:47,912 INFO Order made successfully: /home/frank/original_virtual_doctor/routes/user_routes.py 572
2024-07-13 00:51:49,760 INFO Logging setup successfully: /home/frank/original_virtual_doctor/./app.py 28
2024-07-13 00:51:49,761 INFO DataBase set up successfully: /home/frank/original_virtual_doctor/./app.py 40
2024-07-13 00:51:49,917 INFO Migrations set up successfully: /home/frank/original_virtual_doctor/./app.py 52
2024-07-13 00:51:49,934 INFO Blueprints registered successfully: /home/frank/original_virtual_doctor/./app.py 60
2024-07-13 00:51:49,934 INFO Mail service setup successfully: /home/frank/original_virtual_doctor/./app.py 73
2024-07-13 00:51:49,934 INFO App created successfully: /home/frank/original_virtual_doctor/./app.py 83
2024-07-13 00:52:17,317 INFO Uploaded prescription retrieved: /home/frank/original_virtual_doctor/routes/user_routes.py 424
2024-07-13 00:52:18,403 INFO Prescription searched in database: /home/frank/original_virtual_doctor/routes/user_routes.py 503
2024-07-13 00:52:22,671 INFO Logging setup successfully: /home/frank/original_virtual_doctor/app.py 28
2024-07-13 00:52:22,672 INFO DataBase set up successfully: /home/frank/original_virtual_doctor/app.py 40
2024-07-13 00:52:22,749 INFO Migrations set up successfully: /home/frank/original_virtual_doctor/app.py 52
2024-07-13 00:52:22,773 INFO Blueprints registered successfully: /home/frank/original_virtual_doctor/app.py 60
2024-07-13 00:52:22,773 INFO Mail service setup successfully: /home/frank/original_virtual_doctor/app.py 73
2024-07-13 00:52:22,774 INFO App created successfully: /home/frank/original_virtual_doctor/app.py 83
2024-07-13 00:52:22,775 INFO Order made successfully: /home/frank/original_virtual_doctor/routes/user_routes.py 572
2024-07-13 00:56:08,228 INFO Uploaded prescription retrieved: /home/frank/original_virtual_doctor/routes/user_routes.py 424
2024-07-13 00:56:08,818 INFO Prescription searched in database: /home/frank/original_virtual_doctor/routes/user_routes.py 503
2024-07-13 00:56:24,097 INFO Uploaded prescription retrieved: /home/frank/original_virtual_doctor/routes/user_routes.py 424
2024-07-13 00:56:24,904 INFO Prescription searched in database: /home/frank/original_virtual_doctor/routes/user_routes.py 503
2024-07-13 00:57:10,285 INFO Uploaded prescription retrieved: /home/frank/original_virtual_doctor/routes/user_routes.py 424
2024-07-13 00:57:10,756 INFO Prescription searched in database: /home/frank/original_virtual_doctor/routes/user_routes.py 503
