2024-07-09 00:51:38,371 ERROR (pymysql.err.IntegrityError) (1062, "Duplicate entry '1-3' for key 'stock.pharm_med_unique'")
[SQL: INSERT INTO stock (stock_uuid, price, quant, mfr, pharm_id, meds_id) VALUES (%(stock_uuid)s, %(price)s, %(quant)s, %(mfr)s, %(pharm_id)s, %(meds_id)s)]
[parameters: {'stock_uuid': '65eb3929-9a31-4a67-b224-9690a9c96d40', 'price': '5', 'quant': '4', 'mfr': 'pp', 'pharm_id': 1, 'meds_id': 3}]
(Background on this error at: https://sqlalche.me/e/20/gkpj): /home/frank/original_virtual_doctor/routes/pharm_routes.py 152
Traceback (most recent call last):
  File "/home/frank/.local/lib/python3.10/site-packages/sqlalchemy/engine/base.py", line 1970, in _exec_single_context
    self.dialect.do_execute(
  File "/home/frank/.local/lib/python3.10/site-packages/sqlalchemy/engine/default.py", line 924, in do_execute
    cursor.execute(statement, parameters)
  File "/home/frank/.local/lib/python3.10/site-packages/pymysql/cursors.py", line 153, in execute
    result = self._query(query)
  File "/home/frank/.local/lib/python3.10/site-packages/pymysql/cursors.py", line 322, in _query
    conn.query(q)
  File "/home/frank/.local/lib/python3.10/site-packages/pymysql/connections.py", line 563, in query
    self._affected_rows = self._read_query_result(unbuffered=unbuffered)
  File "/home/frank/.local/lib/python3.10/site-packages/pymysql/connections.py", line 825, in _read_query_result
    result.read()
  File "/home/frank/.local/lib/python3.10/site-packages/pymysql/connections.py", line 1199, in read
    first_packet = self.connection._read_packet()
  File "/home/frank/.local/lib/python3.10/site-packages/pymysql/connections.py", line 775, in _read_packet
    packet.raise_for_error()
  File "/home/frank/.local/lib/python3.10/site-packages/pymysql/protocol.py", line 219, in raise_for_error
    err.raise_mysql_exception(self._data)
  File "/home/frank/.local/lib/python3.10/site-packages/pymysql/err.py", line 150, in raise_mysql_exception
    raise errorclass(errno, errval)
pymysql.err.IntegrityError: (1062, "Duplicate entry '1-3' for key 'stock.pharm_med_unique'")

The above exception was the direct cause of the following exception:

Traceback (most recent call last):
  File "/home/frank/original_virtual_doctor/routes/pharm_routes.py", line 149, in meds
    db.session.commit()
  File "/home/frank/.local/lib/python3.10/site-packages/sqlalchemy/orm/scoping.py", line 597, in commit
    return self._proxied.commit()
  File "/home/frank/.local/lib/python3.10/site-packages/sqlalchemy/orm/session.py", line 1972, in commit
    trans.commit(_to_root=True)
  File "<string>", line 2, in commit
  File "/home/frank/.local/lib/python3.10/site-packages/sqlalchemy/orm/state_changes.py", line 139, in _go
    ret_value = fn(self, *arg, **kw)
  File "/home/frank/.local/lib/python3.10/site-packages/sqlalchemy/orm/session.py", line 1257, in commit
    self._prepare_impl()
  File "<string>", line 2, in _prepare_impl
  File "/home/frank/.local/lib/python3.10/site-packages/sqlalchemy/orm/state_changes.py", line 139, in _go
    ret_value = fn(self, *arg, **kw)
  File "/home/frank/.local/lib/python3.10/site-packages/sqlalchemy/orm/session.py", line 1232, in _prepare_impl
    self.session.flush()
  File "/home/frank/.local/lib/python3.10/site-packages/sqlalchemy/orm/session.py", line 4296, in flush
    self._flush(objects)
  File "/home/frank/.local/lib/python3.10/site-packages/sqlalchemy/orm/session.py", line 4431, in _flush
    with util.safe_reraise():
  File "/home/frank/.local/lib/python3.10/site-packages/sqlalchemy/util/langhelpers.py", line 146, in __exit__
    raise exc_value.with_traceback(exc_tb)
  File "/home/frank/.local/lib/python3.10/site-packages/sqlalchemy/orm/session.py", line 4392, in _flush
    flush_context.execute()
  File "/home/frank/.local/lib/python3.10/site-packages/sqlalchemy/orm/unitofwork.py", line 466, in execute
    rec.execute(self)
  File "/home/frank/.local/lib/python3.10/site-packages/sqlalchemy/orm/unitofwork.py", line 642, in execute
    util.preloaded.orm_persistence.save_obj(
  File "/home/frank/.local/lib/python3.10/site-packages/sqlalchemy/orm/persistence.py", line 93, in save_obj
    _emit_insert_statements(
  File "/home/frank/.local/lib/python3.10/site-packages/sqlalchemy/orm/persistence.py", line 1233, in _emit_insert_statements
    result = connection.execute(
  File "/home/frank/.local/lib/python3.10/site-packages/sqlalchemy/engine/base.py", line 1421, in execute
    return meth(
  File "/home/frank/.local/lib/python3.10/site-packages/sqlalchemy/sql/elements.py", line 514, in _execute_on_connection
    return connection._execute_clauseelement(
  File "/home/frank/.local/lib/python3.10/site-packages/sqlalchemy/engine/base.py", line 1643, in _execute_clauseelement
    ret = self._execute_context(
  File "/home/frank/.local/lib/python3.10/site-packages/sqlalchemy/engine/base.py", line 1849, in _execute_context
    return self._exec_single_context(
  File "/home/frank/.local/lib/python3.10/site-packages/sqlalchemy/engine/base.py", line 1989, in _exec_single_context
    self._handle_dbapi_exception(
  File "/home/frank/.local/lib/python3.10/site-packages/sqlalchemy/engine/base.py", line 2356, in _handle_dbapi_exception
    raise sqlalchemy_exception.with_traceback(exc_info[2]) from e
  File "/home/frank/.local/lib/python3.10/site-packages/sqlalchemy/engine/base.py", line 1970, in _exec_single_context
    self.dialect.do_execute(
  File "/home/frank/.local/lib/python3.10/site-packages/sqlalchemy/engine/default.py", line 924, in do_execute
    cursor.execute(statement, parameters)
  File "/home/frank/.local/lib/python3.10/site-packages/pymysql/cursors.py", line 153, in execute
    result = self._query(query)
  File "/home/frank/.local/lib/python3.10/site-packages/pymysql/cursors.py", line 322, in _query
    conn.query(q)
  File "/home/frank/.local/lib/python3.10/site-packages/pymysql/connections.py", line 563, in query
    self._affected_rows = self._read_query_result(unbuffered=unbuffered)
  File "/home/frank/.local/lib/python3.10/site-packages/pymysql/connections.py", line 825, in _read_query_result
    result.read()
  File "/home/frank/.local/lib/python3.10/site-packages/pymysql/connections.py", line 1199, in read
    first_packet = self.connection._read_packet()
  File "/home/frank/.local/lib/python3.10/site-packages/pymysql/connections.py", line 775, in _read_packet
    packet.raise_for_error()
  File "/home/frank/.local/lib/python3.10/site-packages/pymysql/protocol.py", line 219, in raise_for_error
    err.raise_mysql_exception(self._data)
  File "/home/frank/.local/lib/python3.10/site-packages/pymysql/err.py", line 150, in raise_mysql_exception
    raise errorclass(errno, errval)
sqlalchemy.exc.IntegrityError: (pymysql.err.IntegrityError) (1062, "Duplicate entry '1-3' for key 'stock.pharm_med_unique'")
[SQL: INSERT INTO stock (stock_uuid, price, quant, mfr, pharm_id, meds_id) VALUES (%(stock_uuid)s, %(price)s, %(quant)s, %(mfr)s, %(pharm_id)s, %(meds_id)s)]
[parameters: {'stock_uuid': '65eb3929-9a31-4a67-b224-9690a9c96d40', 'price': '5', 'quant': '4', 'mfr': 'pp', 'pharm_id': 1, 'meds_id': 3}]
(Background on this error at: https://sqlalche.me/e/20/gkpj)
2024-07-09 00:53:19,149 INFO Logging setup successfully: /home/frank/original_virtual_doctor/./app.py 22
2024-07-09 00:53:29,711 INFO Logging setup successfully: /home/frank/original_virtual_doctor/app.py 22
2024-07-09 00:53:34,359 INFO Logging setup successfully: /home/frank/original_virtual_doctor/app.py 22
2024-07-09 00:53:45,142 INFO Logging setup successfully: /home/frank/original_virtual_doctor/./app.py 22
2024-07-09 01:08:43,463 INFO Logging setup successfully: /home/frank/original_virtual_doctor/app.py 22
2024-07-09 01:11:01,002 INFO Logging setup successfully: /home/frank/original_virtual_doctor/./app.py 22
2024-07-09 01:11:04,133 INFO Logging setup successfully: /home/frank/original_virtual_doctor/app.py 22
2024-07-09 01:11:20,389 INFO Logging setup successfully: /home/frank/original_virtual_doctor/./app.py 22
2024-07-09 01:11:25,719 INFO Logging setup successfully: /home/frank/original_virtual_doctor/app.py 22
2024-07-09 01:12:30,494 INFO Logging setup successfully: /home/frank/original_virtual_doctor/app.py 22
2024-07-09 01:12:33,473 INFO Logging setup successfully: /home/frank/original_virtual_doctor/./app.py 22
2024-07-09 01:12:49,989 INFO Logging setup successfully: /home/frank/original_virtual_doctor/app.py 22
2024-07-09 01:14:01,385 INFO Logging setup successfully: /home/frank/original_virtual_doctor/app.py 22
2024-07-09 01:14:04,066 INFO Logging setup successfully: /home/frank/original_virtual_doctor/./app.py 22
2024-07-09 01:14:15,067 INFO Logging setup successfully: /home/frank/original_virtual_doctor/app.py 22
2024-07-09 01:14:27,349 INFO Logging setup successfully: /home/frank/original_virtual_doctor/app.py 22
2024-07-09 01:17:39,305 INFO Logging setup successfully: /home/frank/original_virtual_doctor/app.py 22
2024-07-09 01:17:52,534 INFO Logging setup successfully: /home/frank/original_virtual_doctor/app.py 22
2024-07-09 01:17:55,233 INFO Logging setup successfully: /home/frank/original_virtual_doctor/./app.py 22
2024-07-09 01:17:59,279 INFO Logging setup successfully: /home/frank/original_virtual_doctor/app.py 22
2024-07-09 01:18:10,139 INFO Logging setup successfully: /home/frank/original_virtual_doctor/app.py 22
2024-07-09 01:29:30,560 INFO Homepage accessed: /home/frank/original_virtual_doctor/routes/public_routes.py 18
2024-07-09 01:29:37,522 INFO Homepage accessed: /home/frank/original_virtual_doctor/routes/public_routes.py 18
2024-07-09 01:29:49,787 INFO Homepage accessed: /home/frank/original_virtual_doctor/routes/public_routes.py 18
2024-07-09 01:30:21,959 INFO Homepage accessed: /home/frank/original_virtual_doctor/routes/public_routes.py 18
2024-07-09 01:30:38,144 INFO Homepage accessed: /home/frank/original_virtual_doctor/routes/public_routes.py 18
